Traceback (most recent call last):
  File "/opt/hostedtoolcache/Python/3.7.10/x64/lib/python3.7/site-packages/jupyter_cache/executors/utils.py", line 56, in single_nb_execution
    record_timing=False,
  File "/opt/hostedtoolcache/Python/3.7.10/x64/lib/python3.7/site-packages/nbclient/client.py", line 1112, in execute
    return NotebookClient(nb=nb, resources=resources, km=km, **kwargs).execute()
  File "/opt/hostedtoolcache/Python/3.7.10/x64/lib/python3.7/site-packages/nbclient/util.py", line 74, in wrapped
    return just_run(coro(*args, **kwargs))
  File "/opt/hostedtoolcache/Python/3.7.10/x64/lib/python3.7/site-packages/nbclient/util.py", line 53, in just_run
    return loop.run_until_complete(coro)
  File "/opt/hostedtoolcache/Python/3.7.10/x64/lib/python3.7/asyncio/base_events.py", line 587, in run_until_complete
    return future.result()
  File "/opt/hostedtoolcache/Python/3.7.10/x64/lib/python3.7/site-packages/nbclient/client.py", line 554, in async_execute
    cell, index, execution_count=self.code_cells_executed + 1
  File "/opt/hostedtoolcache/Python/3.7.10/x64/lib/python3.7/site-packages/nbclient/client.py", line 857, in async_execute_cell
    self._check_raise_for_error(cell, exec_reply)
  File "/opt/hostedtoolcache/Python/3.7.10/x64/lib/python3.7/site-packages/nbclient/client.py", line 760, in _check_raise_for_error
    raise CellExecutionError.from_cell_and_msg(cell, exec_reply_content)
nbclient.exceptions.CellExecutionError: An error occurred while executing the following cell:
------------------
dmri_dataset.plot_gradients(cmap="viridis")

------------------

[0;31m---------------------------------------------------------------------------[0m
[0;31mTypeError[0m                                 Traceback (most recent call last)
[0;32m<ipython-input-11-23c8e9a91047>[0m in [0;36m<module>[0;34m[0m
[0;32m----> 1[0;31m [0mdmri_dataset[0m[0;34m.[0m[0mplot_gradients[0m[0;34m([0m[0mcmap[0m[0;34m=[0m[0;34m"viridis"[0m[0;34m)[0m[0;34m[0m[0;34m[0m[0m
[0m
[0;32m/opt/hostedtoolcache/Python/3.7.10/x64/lib/python3.7/site-packages/eddymotion/dmri.py[0m in [0;36mplot_gradients[0;34m(self, **kwargs)[0m
[1;32m    192[0m         return plot_gradients(
[1;32m    193[0m             [0mself[0m[0;34m.[0m[0mgradients[0m[0;34m,[0m[0;34m[0m[0;34m[0m[0m
[0;32m--> 194[0;31m             [0;34m**[0m[0mkwargs[0m[0;34m[0m[0;34m[0m[0m
[0m[1;32m    195[0m         )
[1;32m    196[0m [0;34m[0m[0m

[0;32m/opt/hostedtoolcache/Python/3.7.10/x64/lib/python3.7/site-packages/eddymotion/viz.py[0m in [0;36mplot_gradients[0;34m(gradients, title, ax, spacing, filename, **kwargs)[0m
[1;32m    250[0m [0;34m[0m[0m
[1;32m    251[0m     [0;31m# Visualization after re-projecting all shells to the unit sphere[0m[0;34m[0m[0;34m[0m[0;34m[0m[0m
[0;32m--> 252[0;31m     [0mdraw_points[0m[0;34m([0m[0mgradients[0m[0;34m,[0m [0max[0m[0;34m,[0m [0;34m**[0m[0mkwargs[0m[0;34m)[0m[0;34m[0m[0;34m[0m[0m
[0m[1;32m    253[0m [0;34m[0m[0m
[1;32m    254[0m     [0;32mif[0m [0mtitle[0m[0;34m:[0m[0;34m[0m[0;34m[0m[0m

[0;31mTypeError[0m: draw_points() got an unexpected keyword argument 'cmap'
TypeError: draw_points() got an unexpected keyword argument 'cmap'

